<mujoco model="Dual Arm">
	<compiler angle="degree" coordinate="local" inertiafromgeom="true" autolimits="true" texturedir="PNG"/>

	<option	timestep="0.001" gravity="0 0 -9.81" integrator="Euler" o_solref="0.005 0.2" o_solimp="0.95 0.98 0.01 0.5 2"
					cone="elliptic" jacobian="auto" solver="Newton" tolerance="1e-10" impratio="1.0"/>

	<option>
		<flag gravity="enable" sensornoise="disable" override="enable"/>
	</option>

	<visual>
		<global fovy="45" linewidth="2" glow="0.3"/>
		<quality shadowsize="4096" numslices="28"/>
		<map stiffness="50" stiffnessrot="100"/>
		<scale forcewidth="0.03" contactwidth="0.15" contactheight="0.1" connect="0.1" com="0.2" jointlength="2.5" jointwidth="0.05"
					 actuatorlength="0.5" actuatorwidth="0.3" framelength="1" framewidth="0.03"/>
		<rgba haze="0.6 0.8 0.9 1" force="0 1 0 0.5" com="0 0 1 1"/>
	</visual>

	<default>
		<geom contype="1" conaffinity="1" condim="3" material="MatGnd"/>
		<joint limited="false" damping="0.5" armature="0.1" stiffness="0" frictionloss="0"/>
		<motor gear="100 0 0 0 0 0" ctrllimited="true" ctrlrange="-100 100"/>
	</default>

	<asset>
		<texture name="texplane" type="2d"     builtin="checker"  width="512" height="512" mark="edge"  rgb1="0.2 0.3 0.4" rgb2="0.1 0.1 0.2" markrgb="1 1 1"/>
		<texture name="texgeom"  type="cube"   builtin="flat"     width="512" height="512" mark="cross" rgb1="0.8 0.6 0.4" rgb2="0.8 0.6 0.4" markrgb="1 1 1"/>
		<texture name="sky"      type="skybox" builtin="gradient" width="512" height="512" rgb1="1 1 1" rgb2="0.6 0.8 1"/>

		<material name="MatGnd"   reflectance="0" specular="1" shininess="1" rgba="0 0.4 0.5 1"/>
		<material name="MatGeom"  texture="texgeom" texuniform="true"/>
		<material name="MatPlane" texture="texplane" reflectance='0' texrepeat="1 1" texuniform="true"/>
	</asset>
	<!-- ######################################################################### -->
	
	<worldbody>
		<light directional="true" pos=" 5 -5 5" dir="-0.5  0.5 -1" diffuse="0.3 0.3 0.3" specular="0.0 0.0 0.0" castshadow="false"/>
		<light directional="true" pos=" 5  5 5" dir="-0.5 -0.5 -1" diffuse="0.3 0.3 0.3" specular="0.0 0.0 0.0" castshadow="false"/>
		<light directional="true" pos="-5  5 5" dir=" 0.5 -0.5 -1" diffuse="0.3 0.3 0.3" specular="0.0 0.0 0.0" castshadow="false"/>
		<light directional="true" pos="-5 -5 5" dir=" 0.5  0.5 -1" diffuse="0.3 0.3 0.3" specular="0.0 0.0 0.0" castshadow="false"/>
		<!--light directional="true" pos=" 0  0 5" dir=" 0.0  0.0 -1" diffuse="0.1 0.1 0.1" specular="0.1 0.1 0.1" castshadow="false"/-->

		<!-- Ground Floor -->
		<geom name="Ground Floor" type="plane" pos="0 0 0" size="0 0 100" material="MatPlane"/>
		<geom type="cylinder" pos="0 0 0.25" euler="0 0 0" size="0.05 0.25" rgba="0.4 0.4 0.4 1"/>

		<!-- Torso -->
		<body name="Torso" pos="0 0 0.5">
			<inertial pos="0 0 0.25" mass="20.0"/>
			<joint name="Torso-Yaw" pos="0 0 0" type="free" armature="0"/>
			<geom type="box" pos="0 0 0.25" euler="0 0 0" size="0.07 0.1 0.25" rgba="0 0.4 0.6 1"/>
			<geom type="cylinder" pos="0 0 0.5" euler="90 0 0" size="0.07 0.1" rgba="0 0.4 0.6 1"/>
			<geom type="cylinder" pos="0 -0.11 0.5" euler="90 0 0" size="0.05 0.01" rgba="1 0 0.5 1"/>
			<geom type="cylinder" pos="0  0.11 0.5" euler="90 0 0" size="0.05 0.01" rgba="1 0 0.5 1"/>

			<!-- Right Arm -->
			<body name="Right Shoulder Pitch" pos="0 -0.1 0.5" euler="90 0 0">
				<inertial pos="0 0 0" mass="1.5"/>
				<joint name="RS-Pitch" pos="0 0 0" type="hinge" axis="0 0 1" limited="true" range="-90 90"/>
				<geom type="cylinder" pos="0 0 0.05" size="0.03 0.03" rgba="0.6 0.6 0.5 1"/>

				<body name="Right Shoulder Roll" pos="0 0 0.1" euler="0 90 0">
					<inertial pos="0 -0.15 0" mass="1.5"/>
					<joint name="RS-Roll" pos="0 0 0" type="hinge" axis="0 0 1" limited="true" range="-150 5"/>
					<geom type="cylinder" pos="0 0 0" size="0.04 0.05" rgba="1 0 0.5 1"/>
					<geom type="cylinder" pos="0 -0.2 0" euler="90 0 0" size="0.03 0.2" rgba="0.6 0.6 0.5 1"/>
					<site name="Right EE" type="sphere" pos="0 -0.4 0" euler="90 0 90" rgba="1 0 0 1"/>
				</body>
			</body>
			<!-- End of Right Arm -->

			<!-- Left Arm -->
			<body name="Left Shoulder Pitch" pos="0 0.1 0.5" euler="90 0 0">
				<inertial pos="0 0 0" mass="1.5"/>
				<joint name="LS-Pitch" pos="0 0 0" type="hinge" axis="0 0 1" limited="true" range="-90 90"/>
				<geom type="cylinder" pos="0 0 -0.05" size="0.03 0.03" rgba="0.6 0.6 0.5 1"/>

				<body name="Left Shoulder Roll" pos="0 0 -0.1" euler="0 90 0">
					<inertial pos="0 -0.15 0" mass="1.5"/>
					<joint name="LS-Roll" pos="0 0 0" type="hinge" axis="0 0 1" limited="true" range="-5 150"/>
					<geom type="cylinder" pos="0 0 0" size="0.04 0.05" rgba="1 0 0.5 1"/>
					<geom type="cylinder" pos="0 -0.2 0" euler="90 0 0" size="0.03 0.2" rgba="0.6 0.6 0.5 1"/>
					<site name="Left EE" type="sphere" pos="0 -0.4 0" euler="90 0 0" rgba="1 0 0 1"/>
				</body>
			</body>	<!-- End of Left Arm -->
		</body>	<!-- End of Torse -->
	</worldbody>

	<actuator>
		<motor name="RS-P" gear="50 0 0 0 0 0" joint="RS-Pitch"/>
		<motor name="LS-P" gear="50 0 0 0 0 0" joint="LS-Pitch"/>
		<motor name="RS-R" gear="50 0 0 0 0 0" joint="RS-Roll"/>
		<motor name="LS-R" gear="50 0 0 0 0 0" joint="LS-Roll"/>
	</actuator>

	<!--sensor>
		<force name="Force_sensor" noise="" cutoff="100" site="FTsensor"/>
		<torque name="Torque_sensor" noise="" cutoff="100" site="FTsensor"/>
	</sensor-->
</mujoco>
