<mujoco model="Wheel-legged Humanoid Robot : MAHRU-S(MAHRU-Satyr)">
  <compiler angle="degree" coordinate="local" inertiafromgeom="true" texturedir="PNG"/>

  <option>
    <flag gravity="enable" sensornoise="disable" override="enable"/>
  </option>
  
  <option	timestep="0.001" gravity="0 0 -9.81" integrator="Euler" o_solref="0.005 0.2" o_solimp="0.95 0.98 0.01 0.5 2"
          cone="elliptic" jacobian="auto" solver="Newton" tolerance="1e-10" impratio="1.0"/>

  <visual>
    <global fovy="45" linewidth="2" glow="0.3"/>
    <quality shadowsize="2048" numslices="48"/>
    <map stiffness="50" stiffnessrot="100"/>
    <scale forcewidth="0.03" contactwidth="0.15" contactheight="0.1" connect="0.1" com="0.2" jointlength="2.5" jointwidth="0.05"
           actuatorlength="0.5" actuatorwidth="0.3" framelength="1" framewidth="0.03"/>
    <rgba haze="0.6 0.8 0.9 1" force="1 0 0 0.5" com="0 0 1 1"/>
  </visual>

  <default>
    <geom contype="1" conaffinity="1" condim="3" material="MatGnd"/>
    <joint limited="false" damping="0.1" armature=".1" stiffness="0" frictionloss="0"/>
    <motor gear="100 0 0 0 0 0" ctrllimited="true" ctrlrange="-100 100"/>
  </default>

  <asset>
    <texture name="picfloor" type="2d"     builtin="none" file="Marble-03.png"/>
    <texture name="picmetal" type="2d"     builtin="none" file="MetallicSilver-01.png"/>
    <texture name="picstone" type="2d"     builtin="none" file="Stone-01.png"/>
    <texture name="picwheel" type="2d"     builtin="none" file="Wheel-01.png"/>
    <texture name="picomniw" type="2d"     builtin="none" file="OmniWheel-01.png"/>
    <texture name="texplane" type="2d"     builtin="checker"  width="512" height="512" mark="edge"  rgb1="0.2 0.3 0.4" rgb2="0.1 0.1 0.2" markrgb="1 1 1"/>
    <texture name="texgeom"  type="cube"   builtin="flat"     width="512" height="512" mark="cross" rgb1="0.8 0.6 0.4" rgb2="0.8 0.6 0.4" markrgb="1 1 1"/>
    <texture name="sky"      type="skybox" builtin="gradient" width="512" height="512" rgb1="1 1 1" rgb2="0.6 0.8 1"/>

    <material name="MatGnd"   reflectance="0" specular="1" shininess="1" rgba="0 0.4 0.5 1"/>
    <!--material name="MatGnd"   reflectance="0" specular="1" shininess="1" rgba="1 1 1 1"/-->
    <material name="MatGeom"  texture="texgeom" texuniform="true"/>
    <material name="MatPlane" texture="texplane" reflectance='0' texrepeat="1 1" texuniform="true"/>
    <material name="MatFloor" texture="picfloor" reflectance='0.05' shininess="0.9" texrepeat="2 2" texuniform="true"/>
    <material name="MatStone" texture="picstone"/>
    <material name="MatWheel" texture="picwheel" emission="0.3" reflectance="0.3" shininess="0.5"/>
    <material name="MatOmniW" texture="picomniw" emission="0.3" reflectance="0.3" shininess="0.5"/>
    <material name="MatMetal" texture="picmetal"/>
  </asset>
  <!-- ######################################################################### -->

  <worldbody>
    <light directional="true" pos=" 5 -5 5" dir="-0.5  0.5 -1" diffuse="0.3 0.3 0.3" specular="0.0 0.0 0.0" castshadow="false"/>
    <light directional="true" pos=" 5  5 5" dir="-0.5 -0.5 -1" diffuse="0.3 0.3 0.3" specular="0.0 0.0 0.0" castshadow="false"/>
    <light directional="true" pos="-5  5 5" dir=" 0.5 -0.5 -1" diffuse="0.3 0.3 0.3" specular="0.0 0.0 0.0" castshadow="false"/>
    <light directional="true" pos="-5 -5 5" dir=" 0.5  0.5 -1" diffuse="0.3 0.3 0.3" specular="0.0 0.0 0.0" castshadow="false"/>
    <!--light directional="true" pos=" 0  0 5" dir=" 0.0  0.0 -1" diffuse="0.1 0.1 0.1" specular="0.1 0.1 0.1" castshadow="false"/-->

    <!-- Ground -->
    <geom name="Ground" type="plane" pos="0 0 0" size="0 0 100" material="MatPlane" condim="3"/>

    <!-- ########## Wheel-Legged Humanoid Robot : MAHRU-S ########## -->
    <body name="Pelvis" pos="0 0 0.85" euler="0 0 0">
      <!--freejoint name="Floating-Base"/-->
      <joint name="Floating-Base" type="free"/>
      <inertial pos="0 0 0.15" mass="8.0"/>
      <geom type="box" pos="0 0 0" euler="0 0 0" size="0.06 0.07 0.03" rgba="0.5 0.5 0.5 1"/>
      <geom type="box" pos="0 0 0.18" euler="0 0 0" size="0.07 0.12 0.15" rgba="0.6 0.6 0.6 1"/>
      
      <geom type="box" pos="-0.065 0 -0.05" euler="0 0 0" size="0.005 0.07 0.05" rgba="0.5 0.5 0.5 1"/>
      <geom type="cylinder" pos="-0.065 -0.041 -0.1" euler="0 90 0" size="0.041 0.005" rgba="0.5 0.5 0.5 1"/>
      <geom type="cylinder" pos="-0.065  0.041 -0.1" euler="0 90 0" size="0.041 0.005" rgba="0.5 0.5 0.5 1"/>

      <geom type="box" pos="0.055 -0.041 -0.065" euler="0 0 0" size="0.005 0.025 0.035" rgba="0.5 0.5 0.5 1"/>
      <geom type="cylinder" pos="0.056 -0.041 -0.1" euler="0 90 0" size="0.03 0.006" rgba="0.5 0.5 0.5 1"/>
      <geom type="box" pos="0.055  0.041 -0.065" euler="0 0 0" size="0.005 0.025 0.035" rgba="0.5 0.5 0.5 1"/>
      <geom type="cylinder" pos="0.056 0.041 -0.1" euler="0 90 0" size="0.03 0.006" rgba="0.5 0.5 0.5 1"/>

      <!-- Right/Left Hip Roll Actuator -->
      <geom type="cylinder" pos="-0.1  0.041 -0.1" euler="0 90 0" size="0.041 0.03" rgba="1.0 0.3 0.5 1"/>
      <geom type="cylinder" pos="-0.1 -0.041 -0.1" euler="0 90 0" size="0.041 0.03" rgba="1.0 0.3 0.5 1"/>

      <!-- ===== Right Leg & Wheel ===== -->
      <body name="Right Hip Roll" pos="0 -0.041 -0.1" euler="0 90 0">
        <joint name="Right Hip Roll" type="hinge" axis="0 0 1" armature="0.1" limited="true" range="-90 90"
               springref="0" springdamper="0.05 1"/>
        <inertial pos="0 0 0" mass="2.5"/>
        <geom type="cylinder" pos="0 0 -0.005" euler="0 0 0" size="0.015 0.054" rgba="0.7 0.7 0.7 1"/>

        <!-- Right Hip Pitch Actuator -->
        <geom type="cylinder" pos="0 -0.01 0" euler="90 0 0" size="0.035 0.035" rgba="1.0 0.3 0.5 1"/> 

        <body name="Right Thigh" pos="0 -0.085 0" euler="90 0 0">
          <joint name="Right Hip Pitch" type="hinge" axis ="0 0 1" armature="0.1" limited="true" range="-90 160"
                 springref="0" springdamper="0.5 1"/>
          <inertial pos="0.16 0 0" mass="3.5"/>
          <geom type="cylinder" pos="0 0 0.001" euler="0 0 0" size="0.05 0.041" rgba="0.7 0.7 0.7 1"/>
          <geom type="box" pos="0.135 0 0" euler="0 0 0" size="0.135 0.045 0.04" rgba="0.7 0.7 0.7 1"/>
          <geom type="box" pos="0.295 0 0.025" euler="0 0 0" size="0.025 0.049 0.025" rgba="0.7 0.7 0.7 1"/>
          <geom type="cylinder" pos="0.32 0 0.025" euler="0 0 0" size="0.049 0.025" rgba="0.7 0.7 0.7 1"/>

          <!-- Right Knee Actuator -->
          <geom type="cylinder" pos="0.32 0 -0.015" euler="0 0 0" size="0.035 0.014" rgba="1.0 0.3 0.5 1"/>

          <body name="Right Shin" pos="0.32 0 0" euler="0 0 0">
            <joint name="Right Knee" type="hinge" axis ="0 0 1" armature="0.1" limited="true" range="-150 0"
                   springref="0" springdamper="0.5 1"/>
            <inertial pos="0.25 0 0" mass="3.5"/>
            <geom type="cylinder" pos="0 0 -0.035" euler="0 0 0" size="0.04 0.006" rgba="0.5 0.5 0.5 1"/>
            <geom type="box" pos="0.025 0 -0.035" euler="0 0 0" size="0.025 0.04 0.005" rgba="0.7 0.7 0.7 1"/>
            <geom type="box" pos="0.055 0 0" euler="0 0 0" size="0.005 0.04 0.04" rgba="0.7 0.7 0.7 1"/>
            <geom type="cylinder" pos="0.168 0 0" euler="0 90 0" size="0.04 0.108" rgba="0.7 0.7 0.7 1"/>
            <geom type="box" pos="0.298 0 -0.02" euler="0 0 0" size="0.022 0.040 0.02" rgba="0.7 0.7 0.7 1"/>
            <geom type="cylinder" pos="0.32 0 -0.02" euler="0 0 0" size="0.045 0.02" rgba="0.7 0.7 0.7 1"/>

            <!-- Right Wheel Actuator -->
            <geom type="cylinder" pos="0.32 0 0.025" euler="0 0 0" size="0.045 0.025" rgba="1.0 0.3 0.5 1"/>

            <body name="RightWheel" pos="0.32 0 0.07">
              <joint name="Wheel-R" pos="0 0 0" type="hinge" axis="0 0 1" armature="0.1" ref="0"/>
              <inertial pos="0 0 0" mass="1.5"/>
              <geom name="RW" type="cylinder" pos="0 0 0" size="0.075 0.015" material="MatWheel"/>
            </body>
          </body>
        </body>
      </body>  <!-- End of Right Leg & Wheel -->

      <!-- ===== Left Leg & Wheel ===== -->
      <body name="Left Hip Roll" pos="0 0.041 -0.1" euler="0 90 0">
        <joint name="Left Hip Roll" type="hinge" axis="0 0 1" armature="0.1" limited="true" range="-90 90"
               springref="0" springdamper="0.05 1"/>
        <inertial pos="0 0 0" mass="2.5"/>
        <geom type="cylinder" pos="0 0 -0.005" euler="0 0 0" size="0.015 0.054" rgba="0.7 0.7 0.7 1"/>
        <!-- Left Hip Pitch Actuator -->
        <geom type="cylinder" pos="0 0.01 0" euler="90 0 0" size="0.035 0.035" rgba="1.0 0.3 0.5 1"/>

        <body name="Left Thigh" pos="0 0.085 0" euler="90 0 0">
          <joint name="Left Hip Pitch" type="hinge" axis ="0 0 1" armature="0.1" limited="true" range="-90 160"
                 springref="0" springdamper="0.5 1"/>
          <inertial pos="0.16 0 0" mass="3.5"/>
          <geom type="cylinder" pos="0 0 -0.001" euler="0 0 0" size="0.05 0.041" rgba="0.7 0.7 0.7 1"/>
          <geom type="box" pos="0.135 0 0" euler="0 0 0" size="0.135 0.045 0.04" rgba="0.7 0.7 0.7 1"/>
          <geom type="box" pos="0.295 0 -0.025" euler="0 0 0" size="0.025 0.049 0.025" rgba="0.7 0.7 0.7 1"/>
          <geom type="cylinder" pos="0.32 0 -0.025" euler="0 0 0" size="0.049 0.025" rgba="0.7 0.7 0.7 1"/>

          <!-- Left Knee Actuator -->
          <geom type="cylinder" pos="0.32 0 0.015" euler="0 0 0" size="0.035 0.014" rgba="1.0 0.3 0.5 1"/>

          <body name="Left Shin" pos="0.32 0 0" euler="0 0 0">
            <joint name="Left Knee" type="hinge" axis ="0 0 1" armature="0.1" limited="true" range="-150 0"
                   springref="0" springdamper="0.5 1"/>
            <inertial pos="0.25 0 0" mass="3.5"/>
            <geom type="cylinder" pos="0 0 0.035" euler="0 0 0" size="0.04 0.006" rgba="0.5 0.5 0.5 1"/>
            <geom type="box" pos="0.025 0 0.035" euler="0 0 0" size="0.025 0.04 0.005" rgba="0.7 0.7 0.7 1"/>
            <geom type="box" pos="0.055 0 0" euler="0 0 0" size="0.005 0.04 0.04" rgba="0.7 0.7 0.7 1"/>
            <geom type="cylinder" pos="0.168 0 0" euler="0 90 0" size="0.04 0.108" rgba="0.7 0.7 0.7 1"/>
            <geom type="box" pos="0.298 0 0.02" euler="0 0 0" size="0.022 0.040 0.02" rgba="0.7 0.7 0.7 1"/>
            <geom type="cylinder" pos="0.32 0 0.02" euler="0 0 0" size="0.045 0.02" rgba="0.7 0.7 0.7 1"/>

            <!-- Left Wheel Actuator -->
            <geom type="cylinder" pos="0.32 0 -0.025" euler="0 0 0" size="0.045 0.025" rgba="1.0 0.3 0.5 1"/>

            <body name="LeftWheel" pos="0.32 0 -0.07">
              <joint name="Wheel-L" pos="0 0 0" type="hinge" axis="0 0 1" armature="0.1" ref="0"/>
              <inertial pos="0 0 0" mass="1.5"/>
              <geom name="LW" type="cylinder" pos="0 0 0" size="0.075 0.015" material="MatWheel"/>
            </body>
          </body>
        </body>
      </body>  <!-- End of Left Leg & Wheel -->

    </body>  <!-- ########## End of Wheeled-Humanoid ########## -->
  </worldbody>

  <contact>
    <pair name="GrContact5" geom1="Ground" geom2="RW" friction="10 10 1 1 1"/>
    <pair name="GrContact6" geom1="Ground" geom2="LW" friction="10 10 1 1 1"/>
  </contact>

  <!--actuator>
    <motor name="Wheel-R" ctrllimited="false" gear="1 0 0 0 0 0" joint="Wheel-R"/>
    <motor name="Wheel-L" ctrllimited="false" gear="1 0 0 0 0 0" joint="Wheel-L"/>
    <motor name="Ankle_J" ctrllimited="false" gear="50 0 0 0 0 0" joint="Ankle-Axis"/>
    <motor name="Hip_J" ctrllimited="false" gear="50 0 0 0 0 0" joint="Hip-Axis"/>
  </actuator-->

  <!--sensor>
    <force name="Force_sensor" noise="" cutoff="100" site="FTsensor"/>
    <torque name="Torque_sensor" noise="" cutoff="100" site="FTsensor"/>
  </sensor-->
</mujoco>
