<!-- ======================================================
	This file is part of MuJoCo.     
	Copyright 2009-2016 Roboti LLC.
	
	Model 		:: Baxter from rethink robotics
		Source		: 
		Downloaded	: 
		
	Mujoco		:: Advanced physics simulation engine
		Source		: www.roboti.us
		Version		: 1.31
		Released 	: 23Apr16
		
	Author		:: Vikash Kumar
		Contacts 	: kumar@roboti.us
		Last edits 	: 23May'16, 30Apr16, 26Sept'15, 26July'15
====================================================== -->
<mujoco model="baxter(v1.31)">
	<compiler coordinate="local" angle="radian" meshdir="Meshes/" strippath="false"/>
	<size njmax="795" nconmax="250" nstack="631875" />
	 
	<asset>
		<texture name="sky" type="skybox" builtin="gradient" width="512" height="512" rgb1="1.0 1.0 1.0" rgb2="0.6 0.8 1.0"/>
		<texture name="texgeom"  type="cube"   builtin="flat"     width="512" height="512" rgb1="0.8 0.6 0.4" rgb2="0.8 0.6 0.4"
						 mark="cross" markrgb="1 1 1"/>
		<texture name="texplane" type="2d"     builtin="checker"  width="512" height="512" rgb1="0.2 0.3 0.4" rgb2="0.1 0.1 0.2"
						 mark="edge"  markrgb="1 1 1"/>

		<material name="MatGnd"   emission="0" reflectance="1" specular="1" shininess="1" rgba="0 0.4 0.5 1"/>
		<material name="MatGeom"  texture="texgeom" texuniform="true"/>
		<material name="MatLink"   emission="0" reflectance="1" specular="1" shininess="0.6" rgba="0.5 0.1 0.1 1"/>
		<material name="MatPlane" texture="texplane" reflectance='0' texrepeat="0.2 0.2" texuniform="true"/>		
		
		<mesh name="base_link" file="torso/base_link.STL"/>
		<mesh name="base_link_collision" file="torso/base_link_collision.STL"/>
		<mesh name="PEDESTAL" file="base/PEDESTAL.STL"/>
		<mesh name="pedestal_link_collision" file="base/pedestal_link_collision.STL"/>
		<mesh name="H0" file="head/H0.STL"/>
		<mesh name="H1" file="head/H1.STL"/>
		<mesh name="S0" file="upper_shoulder/S0.STL"/>
		<mesh name="S1" file="lower_shoulder/S1.STL"/>
		<mesh name="E0" file="upper_elbow/E0.STL"/>
		<mesh name="E1" file="lower_elbow/E1.STL"/>
		<mesh name="W0" file="upper_forearm/W0.STL"/>
		<mesh name="W1" file="lower_forearm/W1.STL"/>
		<mesh name="W2" file="wrist/W2.STL"/>
		<mesh name="half_round_tip" file="electric_gripper/fingers/half_round_tip.STL" />
		<mesh name="electric_gripper_base" file="electric_gripper/electric_gripper_base.STL" />
		<mesh name="extended_narrow" file="electric_gripper/fingers/extended_narrow.STL"/>
		<mesh name="paddle_tip" file="electric_gripper/fingers/paddle_tip.STL"/>        
	</asset>

	<visual>
		<global fovy="45" linewidth="2" glow="0.3"/>
		<quality shadowsize="4096" numslices="28"/>
		<map fogstart="1.5" fogend="3" stiffness="50" stiffnessrot="100"/>
		<scale forcewidth="0.03" contactwidth="0.15" contactheight="0.1" connect="0.1" com="0.2" jointlength="2.5" jointwidth="0.05"
					 actuatorlength="0.5" actuatorwidth="0.3" framelength="1" framewidth="0.03"/>
		<rgba haze="0.6 0.8 0.9 1" force="0 1 0 0.5" com="0 0 1 1"/>		
	</visual>
	
	<default>
		<geom margin="0.001"/>
		<joint limited="true" damping="2.0" armature="0.1" frictionloss="0.5"/>
		<default class="viz">
			<geom contype="0" conaffinity="0" group="1" type="mesh" material="MatLink"/>
		</default>
	</default>

	<contact>
		<!--<exclude body1="right_upper_shoulder" body2="torso"/>-->
		<exclude body1="right_upper_shoulder" body2="right_upper_elbow"/>
		<!--<exclude body1="right_lower_shoulder" body2="torso"/>-->

		<!--<exclude body1="left_upper_shoulder" body2="torso"/>-->
		<exclude body1="left_upper_shoulder" body2="left_upper_elbow"/>
		<!--<exclude body1="left_lower_shoulder" body2="torso"/>-->
		
		<!--<exclude body1="r_gripper_r_finger" body2="r_gripper_l_finger"/>
		<exclude body1="l_gripper_r_finger" body2="l_gripper_l_finger"/>-->
	</contact>
	
	<worldbody>
		<!--<light directional="false" cutoff="90" exponent="1" diffuse="1 1 1" specular="0 0 0" pos="1 0 1.5" dir="-1 0 -2.5" castshadow="false"/>
		<geom name="ground" type="plane" pos="0 0 -0.925" size="4 4 .05" rgba="0.7 0.6 0.5 1"/>-->
		<light directional="true" pos=" 5 -5 5" dir="-0.5  0.5 -1" diffuse="0.3 0.3 0.3" specular="0.0 0.0 0.0" castshadow="false"/>
		<light directional="true" pos=" 5  5 5" dir="-0.5 -0.5 -1" diffuse="0.3 0.3 0.3" specular="0.0 0.0 0.0" castshadow="false"/>
		<light directional="true" pos="-5  5 5" dir=" 0.5 -0.5 -1" diffuse="0.3 0.3 0.3" specular="0.0 0.0 0.0" castshadow="false"/>
		<light directional="true" pos="-5 -5 5" dir=" 0.5  0.5 -1" diffuse="0.3 0.3 0.3" specular="0.0 0.0 0.0" castshadow="false"/>

		<geom name="Ground Floor" type="plane" pos="0 0 -0.925" size="4 4 1" material="MatPlane"/>
		
		<geom class="viz" mesh="base_link" rgba="0.5 0.6 0.4 1"/>
		<!--<geom type="mesh" mesh="base_link_collision" rgba="0.7 0.8 0.7 1"/>-->
		<geom class="viz" mesh="PEDESTAL" rgba="0.3 0.3 0.3 1"/>
		<geom type="cylinder" pos="0 0 -0.365" size="0.104 0.277" rgba="1 0 0 1"/>

		<body name="head" pos="0.06 0 0.686">
			<joint name="head_pan" type="hinge" pos="0 0 0" axis="0 0 1" range="-1.5708 1.5708"/>
			<inertial pos="0 0 0" quat="0.339345 0.850736 -0.347392 0.201027" mass="0.547767" diaginertia="0.00474065 0.00461087 0.00199949"/>
			<geom class="viz" mesh="H0" rgba="0.32421875 0.3359375 0.3515625 1"/>
			<geom class="viz" mesh="H1" pos="0.0875 0 0.0023" euler="1.57 0 0" rgba="0.5 0.1 0.1 1"/>
			<geom class="viz" name="display" type="box" pos="0.12 0 -0.005" euler="0 1.831 -1.57" size="0.109 0.08 0.002" rgba=".9 .9 .9 1"/>
		</body>

		<body name="right_upper_shoulder" pos="0.065 -0.26 0.1565" quat="0.923879 0 0 -0.382684">
			<joint name="right_s0" type="hinge" pos="0 0 0" axis="0 0 1" range="-1.70168 1.70168"/>
			<inertial pos="0.01783 0.00086 0.19127" quat="0.975667 0.0673303 -0.206117 0.0325173"
								mass="5.70044" diaginertia="0.0498344 0.0377511 0.0331351"/>
			<geom class="viz" rgba="0.5 0.1 0.1 1" mesh="S0"/>
									
			<body name="right_lower_shoulder" pos="0.069 0 0.27035" quat="0.707107 -0.707107 0 0">
				<joint name="right_s1" type="hinge" pos="0 0 0" axis="0 0 1" range="-2.147 1.047"/>
				<inertial pos="0.06845 0.00269 -0.00529" quat="0.447487 0.536948 0.56425 0.439391"
									mass="3.22698" diaginertia="0.0278991 0.0212327 0.0112937"/>
				<geom class="viz" rgba="0.5 0.1 0.1 1" mesh="S1"/>
											
				<body name="right_upper_elbow" pos="0.102 0 0" quat="0.5 0.5 0.5 0.5">
					<joint name="right_e0" type="hinge" pos="0 0 0" axis="0 0 1" range="-3.05418 3.05418"/>
					<inertial pos="-0.00276 0.00132 0.18086" quat="0.838995 -0.0423128 -0.121287 0.52876"
										mass="4.31272" diaginertia="0.0287695 0.0273625 0.011409"/>
					<geom class="viz" rgba="0.5 0.1 0.1 1" mesh="E0"/>

					<body name="right_lower_elbow" pos="0.069 0 0.26242" quat="0.5 -0.5 -0.5 -0.5">
						<joint name="right_e1" type="hinge" pos="0 0 0" axis="0 0 1" range="-0.05 2.618"/>
						<inertial pos="0.02611 0.00159 -0.01117" quat="0.440433 0.577149 0.562777 0.395221" 
											mass="2.07206" diaginertia="0.0132096 0.00950002 0.00685697"/>
						<geom class="viz" rgba="0.5 0.1 0.1 1" mesh="E1"/>
															
						<body name="right_upper_forearm" pos="0.10359 0 0" quat="0.5 0.5 0.5 0.5">
							<joint name="right_w0" type="hinge" pos="0 0 0" axis="0 0 1" range="-3.059 3.059"/>
							<inertial pos="-0.00168 0.0046 0.13952" quat="0.892709 -0.0256256 0.00446984 0.449882"
												mass="2.24665" diaginertia="0.016916 0.0165511 0.00371123"/>
							<geom class="viz" rgba="0.5 0.1 0.1 1" mesh="W0"/>

							<body name="right_lower_forearm" pos="0.01 0 0.2707" quat="0.5 -0.5 -0.5 -0.5">
								<joint name="right_w1" type="hinge" pos="0 0 0" axis="0 0 1" range="-1.5708 2.094"/>
								<inertial pos="0.06041 0.00697 0.006" quat="0.456911 0.468526 0.475683 0.587743" 
													mass="1.60979" diaginertia="0.00708828 0.00552689 0.00379383"/>
								<geom class="viz" rgba="0.5 0.1 0.1 1" mesh="W1"/>
								<geom type="cylinder" size="0.05 0.01" rgba="1 0.15625 0 1" pos="0 0 0.02"/>

								<body name="right_wrist" pos="0.115975 0 0" quat="0.5 0.5 0.5 0.5">
									<joint name="right_w2" type="hinge" pos="0 0 0" axis="0 0 1" range="-3.059 3.059"/>
									<inertial pos="0.00198 0.00125 0.01855" quat="0.0594843 0.68926 -0.16016 0.704082" 
														mass="0.84218" diaginertia="0.00055 0.00048 0.00041"/>
									<geom class="viz" rgba="0.5 0.6 0.6 1" mesh="W2"/>
									<geom class="viz" mesh="electric_gripper_base" pos="0 0 0.13855" quat="0 0 0.707107 0.707107" rgba="0.6 0.5 0.5 1"/>

									<body name="r_gripper_l_finger" pos="0 -0.0015 0.15855">											
										<joint name="r_gripper_l_finger_joint" pos="0 0 0" axis="0 1 0" type="slide" range="0 0.020833"/>
										<inertial pos="0 0 0" quat="0 0 0 -1" mass="0.03" diaginertia="0.015 0.015 0.015"/>
										<geom class="viz" mesh="extended_narrow" euler="1.57 1.57 0" rgba="0.32421875 0.3359375 0.3515625 1"/>
										<geom class="viz" mesh="half_round_tip" pos="-0.007 0.00725 0.1157" euler="-1.57 0 0" rgba="0 1 0 1"/>
									</body>

									<body name="r_gripper_r_finger" pos="0 0.0015 0.15855">
										<joint name="r_gripper_r_finger_joint" pos="0 0 0" axis="0 1 0" type="slide" range="-0.020833 0" />
										<inertial pos="0 0 0" mass="0.03" diaginertia="0.015 0.015 0.015"/>
										<geom class="viz" mesh="extended_narrow" euler="1.57 -1.57 0" rgba="0.32421875 0.3359375 0.3515625 1"/>
										<geom class="viz" mesh="half_round_tip" pos="0.007 -0.00725 0.1157" euler="-1.57 3.14 0" rgba="0 1 0 1"/>
									</body>
								</body>
							</body>
						</body>
					</body>
				</body>
			</body>
		</body>
				
		<body name="left_upper_shoulder" pos="0.065 0.26 0.1565" quat="0.923879 0 0 0.382684">
			<joint name="left_s0" type="hinge" pos="0 0 0" axis="0 0 1" range="-1.70168 1.70168"/>
			<inertial pos="0.01783 0.00086 0.19127" quat="0.975667 0.0673303 -0.206117 0.0325173"
								mass="5.70044" diaginertia="0.0498344 0.0377511 0.0331351"/>
			<geom class="viz" rgba="0.5 0.1 0.1 1" mesh="S0"/>

			<body name="left_lower_shoulder" pos="0.069 0 0.27035" quat="0.707107 -0.707107 0 0">
				<joint name="left_s1" type="hinge" pos="0 0 0" axis="0 0 1" range="-2.147 1.047"/>
				<inertial pos="0.06845 0.00269 -0.00529" quat="0.447487 0.536948 0.56425 0.439391"
									mass="3.22698" diaginertia="0.0278991 0.0212327 0.0112937"/>
				<geom class="viz" rgba="0.5 0.1 0.1 1" mesh="S1"/>
							
				<body name="left_upper_elbow" pos="0.102 0 0" quat="0.5 0.5 0.5 0.5">
					<joint name="left_e0" type="hinge" pos="0 0 0" axis="0 0 1" range="-3.05418 3.05418"/>
					<inertial pos="-0.00276 0.00132 0.18086" quat="0.838995 -0.0423128 -0.121287 0.52876"
										mass="4.31272" diaginertia="0.0287695 0.0273625 0.011409"/>
					<geom class="viz" rgba="0.5 0.1 0.1 1" mesh="E0"/>
								
					<body name="left_lower_elbow" pos="0.069 0 0.26242" quat="0.5 -0.5 -0.5 -0.5">
						<joint name="left_e1" type="hinge" pos="0 0 0" axis="0 0 1" range="-0.05 2.618"/>
						<inertial pos="0.02611 0.00159 -0.01117" quat="0.440433 0.577149 0.562777 0.395221"
											mass="2.07206" diaginertia="0.0132096 0.00950002 0.00685697"/>
						<geom class="viz" rgba="0.5 0.1 0.1 1" mesh="E1"/>
													
						<body name="left_upper_forearm" pos="0.10359 0 0" quat="0.5 0.5 0.5 0.5">
							<joint name="left_w0" type="hinge" pos="0 0 0" axis="0 0 1" range="-3.059 3.059"/>
							<inertial pos="-0.00168 0.0046 0.13952" quat="0.892709 -0.0256256 0.00446984 0.449882"
												mass="2.24665" diaginertia="0.016916 0.0165511 0.00371123"/>
							<geom class="viz" rgba="0.5 0.1 0.1 1" mesh="W0"/>

							<body name="left_lower_forearm" pos="0.01 0 0.2707" quat="0.5 -0.5 -0.5 -0.5">
								<joint name="left_w1" type="hinge" pos="0 0 0" axis="0 0 1" range="-1.5708 2.094"/>
								<inertial pos="0.06041 0.00697 0.006" quat="0.456911 0.468526 0.475683 0.587743"
													mass="1.60979" diaginertia="0.00708828 0.00552689 0.00379383"/>
								<geom class="viz" rgba="0.5 0.1 0.1 1" mesh="W1"/>
								<geom type="cylinder" size="0.05 0.01" rgba="1 0.15625 0 1" pos="0 0 0.02"/>

								<body name="left_wrist" pos="0.115975 0 0" quat="0.5 0.5 0.5 0.5">
									<joint name="left_w2" type="hinge" pos="0 0 0" axis="0 0 1" range="-3.059 3.059"/>
									<inertial pos="0.00198 0.00125 0.01855" quat="0.0594843 0.68926 -0.16016 0.704082"
														mass="0.84218" diaginertia="0.00055 0.00048 0.00041"/>
									<geom class="viz" rgba="0.5 0.6 0.6 1" mesh="W2"/>
									<geom class="viz" mesh="electric_gripper_base" pos="0 0 0.13855" quat="0 0 0.707107 0.707107" rgba="0.6 0.5 0.5 1"/>


									<body name="l_gripper_l_finger" pos="0 -0.0015 0.15855">
										<joint name="l_gripper_l_finger_joint" pos="0 0 0" axis="0 1 0" type="slide" range="0 0.020833" />
										<inertial pos="0 0 0" quat="0 0 0 -1" mass="0.03" diaginertia="0.015 0.015 0.015" />
										<geom class="viz" mesh="extended_narrow" euler="1.57 1.57 0" rgba="0.32421875 0.3359375 0.3515625 1"/>
										<geom class="viz" mesh="paddle_tip" pos="-0.02 0.00825 0.1157" euler="-1.57 0 0" rgba="0 1 0 1"/>
									</body>
														
									<body name="l_gripper_r_finger" pos="0 0.0015 0.15855">
										<joint name="l_gripper_r_finger_joint" pos="0 0 0" axis="0 1 0" type="slide" range="-0.020833 0" />
										<inertial pos="0 0 0" mass="0.03" diaginertia="0.015 0.015 0.015" />
										<geom class="viz" mesh="extended_narrow" euler="1.57 -1.57 0" rgba="0.32421875 0.3359375 0.3515625 1"/>
										<geom class="viz" mesh="paddle_tip" pos="0.02 -0.00825 0.1157" euler="-1.57 3.14 0" rgba="0 1 0 1"/>
									</body> 
								</body>
							</body>
						</body>
					</body>
				</body>
			</body>
		</body>
	</worldbody>
</mujoco>
